<?xml version="1.0" ?>
<!-- =================================================================================== -->
<!-- |    This document was autogenerated by xacro from ../xacro/base_cabinet.urdf.xacro | -->
<!-- |    EDITING THIS FILE BY HAND IS NOT RECOMMENDED                                 | -->
<!-- =================================================================================== -->
<robot name="base_cabinet">
  <material name="White">
    <color rgba="0.9 0.9 0.9 1.0"/>
  </material>
  <material name="Glass">
    <color rgba="0.9 0.9 0.9 0.9"/>
  </material>
  <material name="Black">
    <color rgba="0.3 0.3 0.3 1.0"/>
  </material>
  <material name="Oak">
    <color rgba="0.89 0.81 0.69 1.0"/>
  </material>
  <!-- Using meter, kg -->
  <!-- https://www.ikea.com.hk/en/products/kitchen-fixed-interiors/kitchen-fixed-interiors/maximera-art-80297276-->
  <!-- Components -->
  <!--  <xacro:macro name="handle" params="prefix parent *origin">-->
  <!--    <link name="${prefix}_handle">-->
  <!--      <visual>-->
  <!--        <origin xyz="0 0 0" rpy="0 0 0"/>-->
  <!--        &lt;!&ndash;        <geometry>&ndash;&gt;-->
  <!--        &lt;!&ndash;          <box size="${worktop_ydim worktop_xdim worktop_zdim}"/>&ndash;&gt;-->
  <!--        &lt;!&ndash;        </geometry>&ndash;&gt;-->
  <!--        <material name="Black"/>-->
  <!--      </visual>-->
  <!--      <collision>-->
  <!--        <origin xyz="0 0 0" rpy="0 0 0"/>-->
  <!--        &lt;!&ndash;        <geometry>&ndash;&gt;-->
  <!--        &lt;!&ndash;          <box size="${worktop_ydim worktop_xdim worktop_zdim}"/>&ndash;&gt;-->
  <!--        &lt;!&ndash;        </geometry>&ndash;&gt;-->
  <!--      </collision>-->
  <!--      <inertial>-->
  <!--        <mass value="${handle_mass}"/>-->
  <!--        &lt;!&ndash;        <origin xyz="0 0 0"/>&ndash;&gt;-->
  <!--        &lt;!&ndash;        <xacro:box_inertia mass="${worktop_mass}" ydim="${worktop_ydim}" xdim="${worktop_xdim}"&ndash;&gt;-->
  <!--        &lt;!&ndash;                           zdim="${worktop_zdim}"/>&ndash;&gt;-->
  <!--      </inertial>-->
  <!--    </link>-->
  <!--    <joint name="{prefix}_handle_joint" type="fixed">-->
  <!--      <parent link="${parent}"/>-->
  <!--      <child link="{prefix}_handle_link"/>-->
  <!--      <xacro:insert_block name="origin"/>-->
  <!--    </joint>-->
  <!--  </xacro:macro>-->
  <link name="base_cabinet_base_link">
    <visual>
      <origin xyz="0 0 0"/>
      <geometry>
        <box size="0.6 1.8 0.08"/>
      </geometry>
      <material name="White"/>
    </visual>
    <collision>
      <origin xyz="0 0 0"/>
      <geometry>
        <box size="0.6 1.8 0.08"/>
      </geometry>
    </collision>
    <inertial>
      <origin xyz="0 0 0"/>
      <mass value="20"/>
      <inertia ixx="5.410666666666668" ixy="0" ixz="0" iyy="0.6106666666666667" iyz="0" izz="6.0"/>
    </inertial>
  </link>
  <link name="base_cabinet_frame_left_side_panel">
    <visual>
      <origin xyz="0 0 0"/>
      <geometry>
        <box size="0.6 0.016 0.8"/>
      </geometry>
      <material name="White"/>
    </visual>
    <collision>
      <origin xyz="0 0 0"/>
      <geometry>
        <box size="0.6 0.016 0.8"/>
      </geometry>
    </collision>
    <inertial>
      <origin xyz="0 0 0"/>
      <mass value="5"/>
      <inertia ixx="0.26677333333333336" ixy="0" ixz="0" iyy="0.4166666666666667" iyz="0" izz="0.15010666666666664"/>
    </inertial>
  </link>
  <joint name="base_cabinet_frame_left_side_panel_joint" type="fixed">
    <origin rpy="0 0 0" xyz="0 0.892 0.44"/>
    <parent link="base_cabinet_base_link"/>
    <child link="base_cabinet_frame_left_side_panel"/>
  </joint>
  <link name="base_cabinet_frame_right_side_panel">
    <visual>
      <origin xyz="0 0 0"/>
      <geometry>
        <box size="0.6 0.016 0.8"/>
      </geometry>
      <material name="White"/>
    </visual>
    <collision>
      <origin xyz="0 0 0"/>
      <geometry>
        <box size="0.6 0.016 0.8"/>
      </geometry>
    </collision>
    <inertial>
      <origin xyz="0 0 0"/>
      <mass value="5"/>
      <inertia ixx="0.26677333333333336" ixy="0" ixz="0" iyy="0.4166666666666667" iyz="0" izz="0.15010666666666664"/>
    </inertial>
  </link>
  <joint name="base_cabinet_frame_right_side_panel_joint" type="fixed">
    <origin rpy="0 0 0" xyz="0 -0.892 0.44"/>
    <parent link="base_cabinet_base_link"/>
    <child link="base_cabinet_frame_right_side_panel"/>
  </joint>
  <link name="base_cabinet_frame_back_panel">
    <visual>
      <origin xyz="0 0 0"/>
      <geometry>
        <box size="0.016 1.8 0.8"/>
      </geometry>
      <material name="White"/>
    </visual>
    <collision>
      <origin xyz="0 0 0"/>
      <geometry>
        <box size="0.016 1.8 0.8"/>
      </geometry>
    </collision>
    <inertial>
      <origin xyz="0 0 0"/>
      <mass value="20"/>
      <inertia ixx="6.466666666666668" ixy="0" ixz="0" iyy="1.0670933333333334" iyz="0" izz="5.400426666666667"/>
    </inertial>
  </link>
  <joint name="base_cabinet_back_panel_joint" type="fixed">
    <origin rpy="0 0 0" xyz="-0.292 0 0.44"/>
    <parent link="base_cabinet_base_link"/>
    <child link="base_cabinet_frame_back_panel"/>
  </joint>
  <link name="base_cabinet_worktop">
    <visual>
      <origin xyz="0 0 0"/>
      <geometry>
        <box size="0.635 1.86 0.028"/>
      </geometry>
      <material name="White"/>
    </visual>
    <collision>
      <origin xyz="0 0 0"/>
      <geometry>
        <box size="0.635 1.86 0.028"/>
      </geometry>
    </collision>
    <inertial>
      <origin xyz="0 0 0"/>
      <mass value="20.65"/>
      <inertia ixx="5.954744133333334" ixy="0" ixz="0" iyy="0.6952321541666667" iyz="0" izz="6.647278020833333"/>
    </inertial>
  </link>
  <joint name="base_cabinet_worktop_joint" type="fixed">
    <origin rpy="0 0 0" xyz="0 0 0.8540000000000001"/>
    <parent link="base_cabinet_base_link"/>
    <child link="base_cabinet_worktop"/>
  </joint>
  <link name="base_cabinet_c1_door">
    <visual>
      <origin xyz="0.008 0.198 0"/>
      <geometry>
        <box size="0.016 0.396 0.796"/>
      </geometry>
      <material name="Oak"/>
    </visual>
    <collision>
      <origin xyz="0.008 0.198 0"/>
      <geometry>
        <box size="0.016 0.396 0.796"/>
      </geometry>
    </collision>
    <inertial>
      <origin xyz="0.008 0.198 0"/>
      <mass value="3.31"/>
      <inertia ixx="0.21802749333333335" ixy="0" ixz="0" iyy="0.1748430266666667" iyz="0" izz="0.04332569333333334"/>
    </inertial>
  </link>
  <joint name="base_cabinet_c1_door_joint" type="revolute">
    <parent link="base_cabinet_base_link"/>
    <child link="base_cabinet_c1_door"/>
    <limit effort="10" lower="0" upper="1.5707963267948966" velocity="1"/>
    <dynamics damping="100" friction="0.1"/>
    <origin xyz="0.3 -0.884 0.44"/>
    <axis xyz="0 0 -1"/>
  </joint>
  <link name="base_cabinet_c2_pull_out_front_panel">
    <visual>
      <origin xyz="0 0 0"/>
      <geometry>
        <box size="0.016 0.197 0.797"/>
      </geometry>
      <material name="Oak"/>
    </visual>
    <collision>
      <origin xyz="0 0 0"/>
      <geometry>
        <box size="0.016 0.197 0.797"/>
      </geometry>
    </collision>
    <inertial>
      <origin xyz="0 0 0"/>
      <mass value="1.66"/>
      <inertia ixx="0.09323915666666666" ixy="0" ixz="0" iyy="0.08790599166666667" iyz="0" izz="0.005403991666666667"/>
    </inertial>
  </link>
  <joint name="base_cabinet_c2_pull_out_front_panel_joint" type="prismatic">
    <parent link="base_cabinet_base_link"/>
    <child link="base_cabinet_c2_pull_out_front_panel"/>
    <limit effort="10" lower="0" upper="0.542" velocity="1"/>
    <dynamics damping="100" friction="0.1"/>
    <origin xyz="0.308 -0.41600000000000004                        0.44"/>
    <axis xyz="1 0 0"/>
  </joint>
  <!--    <xacro:box_link prefix="${prefix}" link_name="${name}_bottom_panel" mass="${drawer_bottom_panel_mass}"-->
  <!--                    xdim="${drawer_bottom_panel_xdim}" ydim="${drawer_bottom_panel_ydim}"-->
  <!--                    zdim="${drawer_bottom_panel_zdim}"-->
  <!--                    material="White"/>-->
  <!--    <joint name="${prefix}_${name}_bottom_panel_joint" type="fixed">-->
  <!--      <parent link="${prefix}_${name}_front_panel"/>-->
  <!--      <child link="${prefix}_${name}_bottom_panel"/>-->
  <!--      <origin xyz="${(-drawer_front_panel_xdim-drawer_bottom_panel_xdim)/2}-->
  <!--                    0 ${(-drawer_front_panel_zdim+drawer_bottom_panel_zdim)/2}"-->
  <!--      />-->
  <!--    </joint>-->
  <!--    <xacro:box_link prefix="${prefix}" link_name="${name}_left_side_panel" mass="${drawer_side_panel_mass}"-->
  <!--                    xdim="${drawer_side_panel_xdim}" ydim="${drawer_side_panel_ydim}" zdim="${drawer_side_panel_zdim}"-->
  <!--                    material="White"/>-->
  <!--    <joint name="${prefix}_${name}_left_side_panel_joint" type="fixed">-->
  <!--      <parent link="${prefix}_${name}_front_panel"/>-->
  <!--      <child link="${prefix}_${name}_left_side_panel"/>-->
  <!--      <origin xyz="${(-drawer_front_panel_xdim-drawer_side_panel_xdim)/2}-->
  <!--                    ${(drawer_front_panel_ydim-drawer_side_panel_ydim)/2} 0"-->
  <!--      />-->
  <!--    </joint>-->
  <!--    <xacro:box_link prefix="${prefix}" link_name="${name}_right_side_panel" mass="${drawer_side_panel_mass}"-->
  <!--                    xdim="${drawer_side_panel_xdim}" ydim="${drawer_side_panel_ydim}" zdim="${drawer_side_panel_zdim}"-->
  <!--                    material="White"/>-->
  <!--    <joint name="${prefix}_${name}_right_side_panel_joint" type="fixed">-->
  <!--      <parent link="${prefix}_${name}_front_panel"/>-->
  <!--      <child link="${prefix}_${name}_right_side_panel"/>-->
  <!--      <origin xyz="${(-drawer_front_panel_xdim-drawer_side_panel_xdim)/2}-->
  <!--                    ${(-drawer_front_panel_ydim+drawer_side_panel_ydim)/2} 0"-->
  <!--      />-->
  <!--    </joint>-->
  <link name="base_cabinet_c3_r1_drawer_front_panel">
    <visual>
      <origin xyz="0 0 0"/>
      <geometry>
        <box size="0.016 0.396 0.196"/>
      </geometry>
      <material name="Oak"/>
    </visual>
    <collision>
      <origin xyz="0 0 0"/>
      <geometry>
        <box size="0.016 0.396 0.196"/>
      </geometry>
    </collision>
    <inertial>
      <origin xyz="0 0 0"/>
      <mass value="0.75"/>
      <inertia ixx="0.012202" ixy="0" ixz="0" iyy="0.0024170000000000003" iyz="0" izz="0.009817000000000001"/>
    </inertial>
  </link>
  <joint name="base_cabinet_c3_r1_drawer_front_panel_joint" type="prismatic">
    <parent link="base_cabinet_base_link"/>
    <child link="base_cabinet_c3_r1_drawer_front_panel"/>
    <limit effort="10" lower="0" upper="0.542" velocity="1"/>
    <dynamics damping="100" friction="0.1"/>
    <origin xyz="0.308 -0.11599999999999999                      0.74"/>
    <axis xyz="1 0 0"/>
  </joint>
  <link name="base_cabinet_c3_r1_drawer_bottom_panel">
    <visual>
      <origin xyz="0 0 0"/>
      <geometry>
        <box size="0.542 0.364 0.016"/>
      </geometry>
      <material name="White"/>
    </visual>
    <collision>
      <origin xyz="0 0 0"/>
      <geometry>
        <box size="0.542 0.364 0.016"/>
      </geometry>
    </collision>
    <inertial>
      <origin xyz="0 0 0"/>
      <mass value="3"/>
      <inertia ixx="0.033188" ixy="0" ixz="0" iyy="0.073505" iyz="0" izz="0.10656500000000001"/>
    </inertial>
  </link>
  <joint name="base_cabinet_c3_r1_drawer_bottom_panel_joint" type="fixed">
    <parent link="base_cabinet_c3_r1_drawer_front_panel"/>
    <child link="base_cabinet_c3_r1_drawer_bottom_panel"/>
    <origin xyz="-0.279                     0 -0.07999999999999999"/>
  </joint>
  <link name="base_cabinet_c3_r1_drawer_left_side_panel">
    <visual>
      <origin xyz="0 0 0"/>
      <geometry>
        <box size="0.542 0.016 0.144"/>
      </geometry>
      <material name="Glass"/>
    </visual>
    <collision>
      <origin xyz="0 0 0"/>
      <geometry>
        <box size="0.542 0.016 0.144"/>
      </geometry>
    </collision>
    <inertial>
      <origin xyz="0 0 0"/>
      <mass value="2"/>
      <inertia ixx="0.003498666666666666" ixy="0" ixz="0" iyy="0.05241666666666667" iyz="0" izz="0.049003333333333336"/>
    </inertial>
  </link>
  <joint name="base_cabinet_c3_r1_drawer_left_side_panel_joint" type="fixed">
    <parent link="base_cabinet_c3_r1_drawer_front_panel"/>
    <child link="base_cabinet_c3_r1_drawer_left_side_panel"/>
    <origin xyz="-0.279                     0.19 0"/>
  </joint>
  <link name="base_cabinet_c3_r1_drawer_right_side_panel">
    <visual>
      <origin xyz="0 0 0"/>
      <geometry>
        <box size="0.542 0.016 0.144"/>
      </geometry>
      <material name="Glass"/>
    </visual>
    <collision>
      <origin xyz="0 0 0"/>
      <geometry>
        <box size="0.542 0.016 0.144"/>
      </geometry>
    </collision>
    <inertial>
      <origin xyz="0 0 0"/>
      <mass value="2"/>
      <inertia ixx="0.003498666666666666" ixy="0" ixz="0" iyy="0.05241666666666667" iyz="0" izz="0.049003333333333336"/>
    </inertial>
  </link>
  <joint name="base_cabinet_c3_r1_drawer_right_side_panel_joint" type="fixed">
    <parent link="base_cabinet_c3_r1_drawer_front_panel"/>
    <child link="base_cabinet_c3_r1_drawer_right_side_panel"/>
    <origin xyz="-0.279                     -0.19 0"/>
  </joint>
  <link name="base_cabinet_c3_r1_drawer_back_panel">
    <visual>
      <origin xyz="0 0 0"/>
      <geometry>
        <box size="0.016 0.364 0.144"/>
      </geometry>
      <material name="White"/>
    </visual>
    <collision>
      <origin xyz="0 0 0"/>
      <geometry>
        <box size="0.016 0.364 0.144"/>
      </geometry>
    </collision>
    <inertial>
      <origin xyz="0 0 0"/>
      <mass value="2"/>
      <inertia ixx="0.025538666666666668" ixy="0" ixz="0" iyy="0.003498666666666666" iyz="0" izz="0.022125333333333334"/>
    </inertial>
  </link>
  <joint name="base_cabinet_c3_r1_drawer_back_panel_joint" type="fixed">
    <parent link="base_cabinet_c3_r1_drawer_front_panel"/>
    <child link="base_cabinet_c3_r1_drawer_back_panel"/>
    <origin xyz="-0.558                     0 0"/>
  </joint>
  <link name="base_cabinet_c3_r2_drawer_front_panel">
    <visual>
      <origin xyz="0 0 0"/>
      <geometry>
        <box size="0.016 0.396 0.196"/>
      </geometry>
      <material name="Oak"/>
    </visual>
    <collision>
      <origin xyz="0 0 0"/>
      <geometry>
        <box size="0.016 0.396 0.196"/>
      </geometry>
    </collision>
    <inertial>
      <origin xyz="0 0 0"/>
      <mass value="0.75"/>
      <inertia ixx="0.012202" ixy="0" ixz="0" iyy="0.0024170000000000003" iyz="0" izz="0.009817000000000001"/>
    </inertial>
  </link>
  <joint name="base_cabinet_c3_r2_drawer_front_panel_joint" type="prismatic">
    <parent link="base_cabinet_base_link"/>
    <child link="base_cabinet_c3_r2_drawer_front_panel"/>
    <limit effort="10" lower="0" upper="0.542" velocity="1"/>
    <dynamics damping="100" friction="0.1"/>
    <origin xyz="0.308 -0.11599999999999999                      0.54"/>
    <axis xyz="1 0 0"/>
  </joint>
  <link name="base_cabinet_c3_r2_drawer_bottom_panel">
    <visual>
      <origin xyz="0 0 0"/>
      <geometry>
        <box size="0.542 0.364 0.016"/>
      </geometry>
      <material name="White"/>
    </visual>
    <collision>
      <origin xyz="0 0 0"/>
      <geometry>
        <box size="0.542 0.364 0.016"/>
      </geometry>
    </collision>
    <inertial>
      <origin xyz="0 0 0"/>
      <mass value="3"/>
      <inertia ixx="0.033188" ixy="0" ixz="0" iyy="0.073505" iyz="0" izz="0.10656500000000001"/>
    </inertial>
  </link>
  <joint name="base_cabinet_c3_r2_drawer_bottom_panel_joint" type="fixed">
    <parent link="base_cabinet_c3_r2_drawer_front_panel"/>
    <child link="base_cabinet_c3_r2_drawer_bottom_panel"/>
    <origin xyz="-0.279                     0 -0.07999999999999999"/>
  </joint>
  <link name="base_cabinet_c3_r2_drawer_left_side_panel">
    <visual>
      <origin xyz="0 0 0"/>
      <geometry>
        <box size="0.542 0.016 0.144"/>
      </geometry>
      <material name="Glass"/>
    </visual>
    <collision>
      <origin xyz="0 0 0"/>
      <geometry>
        <box size="0.542 0.016 0.144"/>
      </geometry>
    </collision>
    <inertial>
      <origin xyz="0 0 0"/>
      <mass value="2"/>
      <inertia ixx="0.003498666666666666" ixy="0" ixz="0" iyy="0.05241666666666667" iyz="0" izz="0.049003333333333336"/>
    </inertial>
  </link>
  <joint name="base_cabinet_c3_r2_drawer_left_side_panel_joint" type="fixed">
    <parent link="base_cabinet_c3_r2_drawer_front_panel"/>
    <child link="base_cabinet_c3_r2_drawer_left_side_panel"/>
    <origin xyz="-0.279                     0.19 0"/>
  </joint>
  <link name="base_cabinet_c3_r2_drawer_right_side_panel">
    <visual>
      <origin xyz="0 0 0"/>
      <geometry>
        <box size="0.542 0.016 0.144"/>
      </geometry>
      <material name="Glass"/>
    </visual>
    <collision>
      <origin xyz="0 0 0"/>
      <geometry>
        <box size="0.542 0.016 0.144"/>
      </geometry>
    </collision>
    <inertial>
      <origin xyz="0 0 0"/>
      <mass value="2"/>
      <inertia ixx="0.003498666666666666" ixy="0" ixz="0" iyy="0.05241666666666667" iyz="0" izz="0.049003333333333336"/>
    </inertial>
  </link>
  <joint name="base_cabinet_c3_r2_drawer_right_side_panel_joint" type="fixed">
    <parent link="base_cabinet_c3_r2_drawer_front_panel"/>
    <child link="base_cabinet_c3_r2_drawer_right_side_panel"/>
    <origin xyz="-0.279                     -0.19 0"/>
  </joint>
  <link name="base_cabinet_c3_r2_drawer_back_panel">
    <visual>
      <origin xyz="0 0 0"/>
      <geometry>
        <box size="0.016 0.364 0.144"/>
      </geometry>
      <material name="White"/>
    </visual>
    <collision>
      <origin xyz="0 0 0"/>
      <geometry>
        <box size="0.016 0.364 0.144"/>
      </geometry>
    </collision>
    <inertial>
      <origin xyz="0 0 0"/>
      <mass value="2"/>
      <inertia ixx="0.025538666666666668" ixy="0" ixz="0" iyy="0.003498666666666666" iyz="0" izz="0.022125333333333334"/>
    </inertial>
  </link>
  <joint name="base_cabinet_c3_r2_drawer_back_panel_joint" type="fixed">
    <parent link="base_cabinet_c3_r2_drawer_front_panel"/>
    <child link="base_cabinet_c3_r2_drawer_back_panel"/>
    <origin xyz="-0.558                     0 0"/>
  </joint>
  <link name="base_cabinet_c3_r3_drawer_front_panel">
    <visual>
      <origin xyz="0 0 0"/>
      <geometry>
        <box size="0.016 0.396 0.196"/>
      </geometry>
      <material name="Oak"/>
    </visual>
    <collision>
      <origin xyz="0 0 0"/>
      <geometry>
        <box size="0.016 0.396 0.196"/>
      </geometry>
    </collision>
    <inertial>
      <origin xyz="0 0 0"/>
      <mass value="0.75"/>
      <inertia ixx="0.012202" ixy="0" ixz="0" iyy="0.0024170000000000003" iyz="0" izz="0.009817000000000001"/>
    </inertial>
  </link>
  <joint name="base_cabinet_c3_r3_drawer_front_panel_joint" type="prismatic">
    <parent link="base_cabinet_base_link"/>
    <child link="base_cabinet_c3_r3_drawer_front_panel"/>
    <limit effort="10" lower="0" upper="0.542" velocity="1"/>
    <dynamics damping="100" friction="0.1"/>
    <origin xyz="0.308 -0.11599999999999999                      0.34"/>
    <axis xyz="1 0 0"/>
  </joint>
  <link name="base_cabinet_c3_r3_drawer_bottom_panel">
    <visual>
      <origin xyz="0 0 0"/>
      <geometry>
        <box size="0.542 0.364 0.016"/>
      </geometry>
      <material name="White"/>
    </visual>
    <collision>
      <origin xyz="0 0 0"/>
      <geometry>
        <box size="0.542 0.364 0.016"/>
      </geometry>
    </collision>
    <inertial>
      <origin xyz="0 0 0"/>
      <mass value="3"/>
      <inertia ixx="0.033188" ixy="0" ixz="0" iyy="0.073505" iyz="0" izz="0.10656500000000001"/>
    </inertial>
  </link>
  <joint name="base_cabinet_c3_r3_drawer_bottom_panel_joint" type="fixed">
    <parent link="base_cabinet_c3_r3_drawer_front_panel"/>
    <child link="base_cabinet_c3_r3_drawer_bottom_panel"/>
    <origin xyz="-0.279                     0 -0.07999999999999999"/>
  </joint>
  <link name="base_cabinet_c3_r3_drawer_left_side_panel">
    <visual>
      <origin xyz="0 0 0"/>
      <geometry>
        <box size="0.542 0.016 0.144"/>
      </geometry>
      <material name="Glass"/>
    </visual>
    <collision>
      <origin xyz="0 0 0"/>
      <geometry>
        <box size="0.542 0.016 0.144"/>
      </geometry>
    </collision>
    <inertial>
      <origin xyz="0 0 0"/>
      <mass value="2"/>
      <inertia ixx="0.003498666666666666" ixy="0" ixz="0" iyy="0.05241666666666667" iyz="0" izz="0.049003333333333336"/>
    </inertial>
  </link>
  <joint name="base_cabinet_c3_r3_drawer_left_side_panel_joint" type="fixed">
    <parent link="base_cabinet_c3_r3_drawer_front_panel"/>
    <child link="base_cabinet_c3_r3_drawer_left_side_panel"/>
    <origin xyz="-0.279                     0.19 0"/>
  </joint>
  <link name="base_cabinet_c3_r3_drawer_right_side_panel">
    <visual>
      <origin xyz="0 0 0"/>
      <geometry>
        <box size="0.542 0.016 0.144"/>
      </geometry>
      <material name="Glass"/>
    </visual>
    <collision>
      <origin xyz="0 0 0"/>
      <geometry>
        <box size="0.542 0.016 0.144"/>
      </geometry>
    </collision>
    <inertial>
      <origin xyz="0 0 0"/>
      <mass value="2"/>
      <inertia ixx="0.003498666666666666" ixy="0" ixz="0" iyy="0.05241666666666667" iyz="0" izz="0.049003333333333336"/>
    </inertial>
  </link>
  <joint name="base_cabinet_c3_r3_drawer_right_side_panel_joint" type="fixed">
    <parent link="base_cabinet_c3_r3_drawer_front_panel"/>
    <child link="base_cabinet_c3_r3_drawer_right_side_panel"/>
    <origin xyz="-0.279                     -0.19 0"/>
  </joint>
  <link name="base_cabinet_c3_r3_drawer_back_panel">
    <visual>
      <origin xyz="0 0 0"/>
      <geometry>
        <box size="0.016 0.364 0.144"/>
      </geometry>
      <material name="White"/>
    </visual>
    <collision>
      <origin xyz="0 0 0"/>
      <geometry>
        <box size="0.016 0.364 0.144"/>
      </geometry>
    </collision>
    <inertial>
      <origin xyz="0 0 0"/>
      <mass value="2"/>
      <inertia ixx="0.025538666666666668" ixy="0" ixz="0" iyy="0.003498666666666666" iyz="0" izz="0.022125333333333334"/>
    </inertial>
  </link>
  <joint name="base_cabinet_c3_r3_drawer_back_panel_joint" type="fixed">
    <parent link="base_cabinet_c3_r3_drawer_front_panel"/>
    <child link="base_cabinet_c3_r3_drawer_back_panel"/>
    <origin xyz="-0.558                     0 0"/>
  </joint>
  <link name="base_cabinet_c3_r4_drawer_front_panel">
    <visual>
      <origin xyz="0 0 0"/>
      <geometry>
        <box size="0.016 0.396 0.196"/>
      </geometry>
      <material name="Oak"/>
    </visual>
    <collision>
      <origin xyz="0 0 0"/>
      <geometry>
        <box size="0.016 0.396 0.196"/>
      </geometry>
    </collision>
    <inertial>
      <origin xyz="0 0 0"/>
      <mass value="0.75"/>
      <inertia ixx="0.012202" ixy="0" ixz="0" iyy="0.0024170000000000003" iyz="0" izz="0.009817000000000001"/>
    </inertial>
  </link>
  <joint name="base_cabinet_c3_r4_drawer_front_panel_joint" type="prismatic">
    <parent link="base_cabinet_base_link"/>
    <child link="base_cabinet_c3_r4_drawer_front_panel"/>
    <limit effort="10" lower="0" upper="0.542" velocity="1"/>
    <dynamics damping="100" friction="0.1"/>
    <origin xyz="0.308 -0.11599999999999999                      0.14"/>
    <axis xyz="1 0 0"/>
  </joint>
  <link name="base_cabinet_c3_r4_drawer_bottom_panel">
    <visual>
      <origin xyz="0 0 0"/>
      <geometry>
        <box size="0.542 0.364 0.016"/>
      </geometry>
      <material name="White"/>
    </visual>
    <collision>
      <origin xyz="0 0 0"/>
      <geometry>
        <box size="0.542 0.364 0.016"/>
      </geometry>
    </collision>
    <inertial>
      <origin xyz="0 0 0"/>
      <mass value="3"/>
      <inertia ixx="0.033188" ixy="0" ixz="0" iyy="0.073505" iyz="0" izz="0.10656500000000001"/>
    </inertial>
  </link>
  <joint name="base_cabinet_c3_r4_drawer_bottom_panel_joint" type="fixed">
    <parent link="base_cabinet_c3_r4_drawer_front_panel"/>
    <child link="base_cabinet_c3_r4_drawer_bottom_panel"/>
    <origin xyz="-0.279                     0 -0.07999999999999999"/>
  </joint>
  <link name="base_cabinet_c3_r4_drawer_left_side_panel">
    <visual>
      <origin xyz="0 0 0"/>
      <geometry>
        <box size="0.542 0.016 0.144"/>
      </geometry>
      <material name="Glass"/>
    </visual>
    <collision>
      <origin xyz="0 0 0"/>
      <geometry>
        <box size="0.542 0.016 0.144"/>
      </geometry>
    </collision>
    <inertial>
      <origin xyz="0 0 0"/>
      <mass value="2"/>
      <inertia ixx="0.003498666666666666" ixy="0" ixz="0" iyy="0.05241666666666667" iyz="0" izz="0.049003333333333336"/>
    </inertial>
  </link>
  <joint name="base_cabinet_c3_r4_drawer_left_side_panel_joint" type="fixed">
    <parent link="base_cabinet_c3_r4_drawer_front_panel"/>
    <child link="base_cabinet_c3_r4_drawer_left_side_panel"/>
    <origin xyz="-0.279                     0.19 0"/>
  </joint>
  <link name="base_cabinet_c3_r4_drawer_right_side_panel">
    <visual>
      <origin xyz="0 0 0"/>
      <geometry>
        <box size="0.542 0.016 0.144"/>
      </geometry>
      <material name="Glass"/>
    </visual>
    <collision>
      <origin xyz="0 0 0"/>
      <geometry>
        <box size="0.542 0.016 0.144"/>
      </geometry>
    </collision>
    <inertial>
      <origin xyz="0 0 0"/>
      <mass value="2"/>
      <inertia ixx="0.003498666666666666" ixy="0" ixz="0" iyy="0.05241666666666667" iyz="0" izz="0.049003333333333336"/>
    </inertial>
  </link>
  <joint name="base_cabinet_c3_r4_drawer_right_side_panel_joint" type="fixed">
    <parent link="base_cabinet_c3_r4_drawer_front_panel"/>
    <child link="base_cabinet_c3_r4_drawer_right_side_panel"/>
    <origin xyz="-0.279                     -0.19 0"/>
  </joint>
  <link name="base_cabinet_c3_r4_drawer_back_panel">
    <visual>
      <origin xyz="0 0 0"/>
      <geometry>
        <box size="0.016 0.364 0.144"/>
      </geometry>
      <material name="White"/>
    </visual>
    <collision>
      <origin xyz="0 0 0"/>
      <geometry>
        <box size="0.016 0.364 0.144"/>
      </geometry>
    </collision>
    <inertial>
      <origin xyz="0 0 0"/>
      <mass value="2"/>
      <inertia ixx="0.025538666666666668" ixy="0" ixz="0" iyy="0.003498666666666666" iyz="0" izz="0.022125333333333334"/>
    </inertial>
  </link>
  <joint name="base_cabinet_c3_r4_drawer_back_panel_joint" type="fixed">
    <parent link="base_cabinet_c3_r4_drawer_front_panel"/>
    <child link="base_cabinet_c3_r4_drawer_back_panel"/>
    <origin xyz="-0.558                     0 0"/>
  </joint>
  <link name="base_cabinet_c4_door">
    <visual>
      <origin xyz="0.008 0.198 0"/>
      <geometry>
        <box size="0.016 0.396 0.796"/>
      </geometry>
      <material name="Oak"/>
    </visual>
    <collision>
      <origin xyz="0.008 0.198 0"/>
      <geometry>
        <box size="0.016 0.396 0.796"/>
      </geometry>
    </collision>
    <inertial>
      <origin xyz="0.008 0.198 0"/>
      <mass value="3.31"/>
      <inertia ixx="0.21802749333333335" ixy="0" ixz="0" iyy="0.1748430266666667" iyz="0" izz="0.04332569333333334"/>
    </inertial>
  </link>
  <joint name="base_cabinet_c4_door_joint" type="revolute">
    <parent link="base_cabinet_base_link"/>
    <child link="base_cabinet_c4_door"/>
    <limit effort="10" lower="0" upper="1.5707963267948966" velocity="1"/>
    <dynamics damping="100" friction="0.1"/>
    <origin xyz="0.3 0.08399999999999996 0.44"/>
    <axis xyz="0 0 -1"/>
  </joint>
  <link name="base_cabinet_c5_door">
    <visual>
      <origin xyz="0.008 -0.198 0"/>
      <geometry>
        <box size="0.016 0.396 0.796"/>
      </geometry>
      <material name="Oak"/>
    </visual>
    <collision>
      <origin xyz="0.008 -0.198 0"/>
      <geometry>
        <box size="0.016 0.396 0.796"/>
      </geometry>
    </collision>
    <inertial>
      <origin xyz="0.008 -0.198 0"/>
      <mass value="3.31"/>
      <inertia ixx="0.21802749333333335" ixy="0" ixz="0" iyy="0.1748430266666667" iyz="0" izz="0.04332569333333334"/>
    </inertial>
  </link>
  <joint name="base_cabinet_c5_door_joint" type="revolute">
    <parent link="base_cabinet_base_link"/>
    <child link="base_cabinet_c5_door"/>
    <limit effort="10" lower="0" upper="1.5707963267948966" velocity="1"/>
    <dynamics damping="100" friction="0.1"/>
    <origin xyz="0.3 0.884 0.44"/>
    <axis xyz="0 0 1"/>
  </joint>
</robot>

