<?xml version="1.0" ?>
<!-- =================================================================================== -->
<!-- |    This document was autogenerated by xacro from ../xacro/wall_cabinet.urdf.xacro | -->
<!-- |    EDITING THIS FILE BY HAND IS NOT RECOMMENDED                                 | -->
<!-- =================================================================================== -->
<robot name="wall_cabinet">
  <material name="White">
    <color rgba="0.9 0.9 0.9 1.0"/>
  </material>
  <material name="Glass">
    <color rgba="0.9 0.9 0.9 0.9"/>
  </material>
  <material name="Black">
    <color rgba="0.3 0.3 0.3 1.0"/>
  </material>
  <material name="Oak">
    <color rgba="0.89 0.81 0.69 1.0"/>
  </material>
  <!--  <xacro:macro name="handle" params="prefix parent *origin">-->
  <!--    <link name="${prefix}_handle">-->
  <!--      <visual>-->
  <!--        <origin xyz="0 0 0" rpy="0 0 0"/>-->
  <!--        &lt;!&ndash;        <geometry>&ndash;&gt;-->
  <!--        &lt;!&ndash;          <box size="${worktop_ydim worktop_xdim worktop_zdim}"/>&ndash;&gt;-->
  <!--        &lt;!&ndash;        </geometry>&ndash;&gt;-->
  <!--        <material name="Black"/>-->
  <!--      </visual>-->
  <!--      <collision>-->
  <!--        <origin xyz="0 0 0" rpy="0 0 0"/>-->
  <!--        &lt;!&ndash;        <geometry>&ndash;&gt;-->
  <!--        &lt;!&ndash;          <box size="${worktop_ydim worktop_xdim worktop_zdim}"/>&ndash;&gt;-->
  <!--        &lt;!&ndash;        </geometry>&ndash;&gt;-->
  <!--      </collision>-->
  <!--      <inertial>-->
  <!--        <mass value="${handle_mass}"/>-->
  <!--        &lt;!&ndash;        <origin xyz="0 0 0"/>&ndash;&gt;-->
  <!--        &lt;!&ndash;        <xacro:box_inertia mass="${worktop_mass}" ydim="${worktop_ydim}" xdim="${worktop_xdim}"&ndash;&gt;-->
  <!--        &lt;!&ndash;                           zdim="${worktop_zdim}"/>&ndash;&gt;-->
  <!--      </inertial>-->
  <!--    </link>-->
  <!--    <joint name="{prefix}_handle_joint" type="fixed">-->
  <!--      <parent link="${parent}"/>-->
  <!--      <child link="{prefix}_handle_link"/>-->
  <!--      <xacro:insert_block name="origin"/>-->
  <!--    </joint>-->
  <!--  </xacro:macro>-->
  <!-- Using meter, kg -->
  <link name="wc_frame_back_panel">
    <visual>
      <origin xyz="0 0 0"/>
      <geometry>
        <box size="0.016 1 0.81"/>
      </geometry>
      <material name="White"/>
    </visual>
    <collision>
      <origin xyz="0 0 0"/>
      <geometry>
        <box size="0.016 1 0.81"/>
      </geometry>
    </collision>
    <inertial>
      <origin xyz="0 0 0"/>
      <mass value="20"/>
      <inertia ixx="2.7601666666666667" ixy="0" ixz="0" iyy="1.093926666666667" iyz="0" izz="1.6670933333333335"/>
    </inertial>
  </link>
  <link name="wc_frame_left_side_panel">
    <visual>
      <origin xyz="0 0 0"/>
      <geometry>
        <box size="0.374 0.016 0.81"/>
      </geometry>
      <material name="White"/>
    </visual>
    <collision>
      <origin xyz="0 0 0"/>
      <geometry>
        <box size="0.374 0.016 0.81"/>
      </geometry>
    </collision>
    <inertial>
      <origin xyz="0 0 0"/>
      <mass value="10"/>
      <inertia ixx="0.5469633333333335" ixy="0" ixz="0" iyy="0.6633133333333334" iyz="0" izz="0.11677666666666668"/>
    </inertial>
  </link>
  <joint name="wc_frame_left_side_panel_joint" type="fixed">
    <origin rpy="0 0 0" xyz="0.179                    0.492 0"/>
    <parent link="wc_frame_back_panel"/>
    <child link="wc_frame_left_side_panel"/>
  </joint>
  <link name="wc_frame_right_side_panel">
    <visual>
      <origin xyz="0 0 0"/>
      <geometry>
        <box size="0.374 0.016 0.81"/>
      </geometry>
      <material name="White"/>
    </visual>
    <collision>
      <origin xyz="0 0 0"/>
      <geometry>
        <box size="0.374 0.016 0.81"/>
      </geometry>
    </collision>
    <inertial>
      <origin xyz="0 0 0"/>
      <mass value="10"/>
      <inertia ixx="0.5469633333333335" ixy="0" ixz="0" iyy="0.6633133333333334" iyz="0" izz="0.11677666666666668"/>
    </inertial>
  </link>
  <joint name="wc_frame_right_side_panel_joint" type="fixed">
    <origin rpy="0 0 0" xyz="0.179                    -0.492 0"/>
    <parent link="wc_frame_back_panel"/>
    <child link="wc_frame_right_side_panel"/>
  </joint>
  <link name="wc_frame_top_panel">
    <visual>
      <origin xyz="0 0 0"/>
      <geometry>
        <box size="0.374 1 0.016"/>
      </geometry>
      <material name="White"/>
    </visual>
    <collision>
      <origin xyz="0 0 0"/>
      <geometry>
        <box size="0.374 1 0.016"/>
      </geometry>
    </collision>
    <inertial>
      <origin xyz="0 0 0"/>
      <mass value="20"/>
      <inertia ixx="1.6670933333333335" ixy="0" ixz="0" iyy="0.23355333333333336" iyz="0" izz="1.8997933333333334"/>
    </inertial>
  </link>
  <joint name="wc_frame_top_panel_joint" type="fixed">
    <origin rpy="0 0 0" xyz="0.179 0                    0.397"/>
    <parent link="wc_frame_back_panel"/>
    <child link="wc_frame_top_panel"/>
  </joint>
  <link name="wc_frame_bottom_panel">
    <visual>
      <origin xyz="0 0 0"/>
      <geometry>
        <box size="0.374 1 0.016"/>
      </geometry>
      <material name="White"/>
    </visual>
    <collision>
      <origin xyz="0 0 0"/>
      <geometry>
        <box size="0.374 1 0.016"/>
      </geometry>
    </collision>
    <inertial>
      <origin xyz="0 0 0"/>
      <mass value="20"/>
      <inertia ixx="1.6670933333333335" ixy="0" ixz="0" iyy="0.23355333333333336" iyz="0" izz="1.8997933333333334"/>
    </inertial>
  </link>
  <joint name="wc_frame_bottom_panel_joint" type="fixed">
    <origin rpy="0 0 0" xyz="0.179 0                    -0.397"/>
    <parent link="wc_frame_back_panel"/>
    <child link="wc_frame_bottom_panel"/>
  </joint>
  <link name="wall_cabinet_c1_door">
    <visual>
      <origin xyz="0.008 0.298 0"/>
      <geometry>
        <box size="0.016 0.596 0.806"/>
      </geometry>
      <material name="Oak"/>
    </visual>
    <collision>
      <origin xyz="0.008 0.298 0"/>
      <geometry>
        <box size="0.016 0.596 0.806"/>
      </geometry>
    </collision>
    <inertial>
      <origin xyz="0.008 0.298 0"/>
      <mass value="3.31"/>
      <inertia ixx="0.2771716766666667" ixy="0" ixz="0" iyy="0.1792618766666667" iyz="0" izz="0.09805102666666665"/>
    </inertial>
  </link>
  <joint name="wall_cabinet_c1_door_joint" type="revolute">
    <parent link="wc_frame_back_panel"/>
    <child link="wall_cabinet_c1_door"/>
    <limit effort="10" lower="0" upper="1.5707963267948966" velocity="1"/>
    <dynamics damping="100" friction="0.1"/>
    <origin xyz="0.366 -0.5 0"/>
    <axis xyz="0 0 -1"/>
  </joint>
  <link name="wall_cabinet_c2_door">
    <visual>
      <origin xyz="0.008 -0.198 0"/>
      <geometry>
        <box size="0.016 0.396 0.806"/>
      </geometry>
      <material name="Oak"/>
    </visual>
    <collision>
      <origin xyz="0.008 -0.198 0"/>
      <geometry>
        <box size="0.016 0.396 0.806"/>
      </geometry>
    </collision>
    <inertial>
      <origin xyz="0.008 -0.198 0"/>
      <mass value="3.31"/>
      <inertia ixx="0.22244634333333338" ixy="0" ixz="0" iyy="0.1792618766666667" iyz="0" izz="0.04332569333333334"/>
    </inertial>
  </link>
  <joint name="wall_cabinet_c2_door_joint" type="revolute">
    <parent link="wc_frame_back_panel"/>
    <child link="wall_cabinet_c2_door"/>
    <limit effort="10" lower="0" upper="1.5707963267948966" velocity="1"/>
    <dynamics damping="100" friction="0.1"/>
    <origin xyz="0.366 0.5 0"/>
    <axis xyz="0 0 1"/>
  </joint>
</robot>

