<?xml version="1.0" ?>
<!-- =================================================================================== -->
<!-- |    This document was autogenerated by xacro from ../xacro/wall_cabinet.urdf.xacro | -->
<!-- |    EDITING THIS FILE BY HAND IS NOT RECOMMENDED                                 | -->
<!-- =================================================================================== -->
<robot name="wall_cabinet">
  <material name="White">
    <color rgba="0.9 0.9 0.9 1.0"/>
  </material>
  <material name="Glass">
    <color rgba="0.9 0.9 0.9 0.9"/>
  </material>
  <material name="Black">
    <color rgba="0.3 0.3 0.3 1.0"/>
  </material>
  <material name="Oak">
    <color rgba="0.89 0.81 0.69 1.0"/>
  </material>
  <material name="LightGreen">
    <color rgba="0.8 1 0.8 1.0"/>
  </material>
  <!-- Using meter, kg -->
  <!-- https://www.ikea.com.hk/en/products/kitchen-fixed-interiors/kitchen-fixed-interiors/maximera-art-80297276-->
  <link name="wc_frame_back_panel">
    <visual>
      <origin xyz="0 0 0"/>
      <geometry>
        <box size="0.016 1 0.81"/>
      </geometry>
      <material name="White"/>
    </visual>
    <collision>
      <origin xyz="0 0 0"/>
      <geometry>
        <box size="0.016 1 0.81"/>
      </geometry>
    </collision>
    <inertial>
      <origin xyz="0 0 0"/>
      <mass value="20"/>
      <inertia ixx="2.7601666666666667" ixy="0" ixz="0" iyy="1.093926666666667" iyz="0" izz="1.6670933333333335"/>
    </inertial>
  </link>
  <link name="wc_frame_left_side_panel">
    <visual>
      <origin xyz="0 0 0"/>
      <geometry>
        <box size="0.39 0.016 0.81"/>
      </geometry>
      <material name="White"/>
    </visual>
    <collision>
      <origin xyz="0 0 0"/>
      <geometry>
        <box size="0.39 0.016 0.81"/>
      </geometry>
    </collision>
    <inertial>
      <origin xyz="0 0 0"/>
      <mass value="10"/>
      <inertia ixx="0.5469633333333335" ixy="0" ixz="0" iyy="0.6735000000000001" iyz="0" izz="0.12696333333333334"/>
    </inertial>
  </link>
  <joint name="wc_frame_left_side_panel_joint" type="fixed">
    <origin rpy="0 0 0" xyz="0.187                    0.492 0"/>
    <parent link="wc_frame_back_panel"/>
    <child link="wc_frame_left_side_panel"/>
  </joint>
  <link name="wc_frame_right_side_panel">
    <visual>
      <origin xyz="0 0 0"/>
      <geometry>
        <box size="0.39 0.016 0.81"/>
      </geometry>
      <material name="White"/>
    </visual>
    <collision>
      <origin xyz="0 0 0"/>
      <geometry>
        <box size="0.39 0.016 0.81"/>
      </geometry>
    </collision>
    <inertial>
      <origin xyz="0 0 0"/>
      <mass value="10"/>
      <inertia ixx="0.5469633333333335" ixy="0" ixz="0" iyy="0.6735000000000001" iyz="0" izz="0.12696333333333334"/>
    </inertial>
  </link>
  <joint name="wc_frame_right_side_panel_joint" type="fixed">
    <origin rpy="0 0 0" xyz="0.187                    -0.492 0"/>
    <parent link="wc_frame_back_panel"/>
    <child link="wc_frame_right_side_panel"/>
  </joint>
  <link name="wc_frame_top_panel">
    <visual>
      <origin xyz="0 0 0"/>
      <geometry>
        <box size="0.39 1 0.016"/>
      </geometry>
      <material name="White"/>
    </visual>
    <collision>
      <origin xyz="0 0 0"/>
      <geometry>
        <box size="0.39 1 0.016"/>
      </geometry>
    </collision>
    <inertial>
      <origin xyz="0 0 0"/>
      <mass value="20"/>
      <inertia ixx="1.6670933333333335" ixy="0" ixz="0" iyy="0.2539266666666667" iyz="0" izz="1.9201666666666666"/>
    </inertial>
  </link>
  <joint name="wc_frame_top_panel_joint" type="fixed">
    <origin rpy="0 0 0" xyz="0.187 0                    0.397"/>
    <parent link="wc_frame_back_panel"/>
    <child link="wc_frame_top_panel"/>
  </joint>
  <link name="wc_frame_bottom_panel">
    <visual>
      <origin xyz="0 0 0"/>
      <geometry>
        <box size="0.39 1 0.016"/>
      </geometry>
      <material name="White"/>
    </visual>
    <collision>
      <origin xyz="0 0 0"/>
      <geometry>
        <box size="0.39 1 0.016"/>
      </geometry>
    </collision>
    <inertial>
      <origin xyz="0 0 0"/>
      <mass value="20"/>
      <inertia ixx="1.6670933333333335" ixy="0" ixz="0" iyy="0.2539266666666667" iyz="0" izz="1.9201666666666666"/>
    </inertial>
  </link>
  <joint name="wc_frame_bottom_panel_joint" type="fixed">
    <origin rpy="0 0 0" xyz="0.187 0                    -0.397"/>
    <parent link="wc_frame_back_panel"/>
    <child link="wc_frame_bottom_panel"/>
  </joint>
  <link name="wc_frame_c1_v_shelf">
    <visual>
      <origin xyz="0 0 0"/>
      <geometry>
        <box size="0.39 0.04 0.81"/>
      </geometry>
      <material name="White"/>
    </visual>
    <collision>
      <origin xyz="0 0 0"/>
      <geometry>
        <box size="0.39 0.04 0.81"/>
      </geometry>
    </collision>
    <inertial>
      <origin xyz="0 0 0"/>
      <mass value="10"/>
      <inertia ixx="0.5480833333333335" ixy="0" ixz="0" iyy="0.6735000000000001" iyz="0" izz="0.12808333333333333"/>
    </inertial>
  </link>
  <joint name="wc_frame_c1_v_shelf_joint" type="fixed">
    <origin xyz="0.187 0.09999999999999998 0"/>
    <parent link="wc_frame_back_panel"/>
    <child link="wc_frame_c1_v_shelf"/>
  </joint>
  <link name="wc_frame_h1_shelf">
    <visual>
      <origin xyz="0 0 0"/>
      <geometry>
        <box size="0.39 1 0.02"/>
      </geometry>
      <material name="White"/>
    </visual>
    <collision>
      <origin xyz="0 0 0"/>
      <geometry>
        <box size="0.39 1 0.02"/>
      </geometry>
    </collision>
    <inertial>
      <origin xyz="0 0 0"/>
      <mass value="10"/>
      <inertia ixx="0.8336666666666667" ixy="0" ixz="0" iyy="0.12708333333333335" iyz="0" izz="0.9600833333333333"/>
    </inertial>
  </link>
  <joint name="wc_frame_h1_shelf_joint" type="fixed">
    <origin xyz="0.187 0 0.065"/>
    <parent link="wc_frame_back_panel"/>
    <child link="wc_frame_h1_shelf"/>
  </joint>
  <link name="wc_frame_h2_shelf">
    <visual>
      <origin xyz="0 0 0"/>
      <geometry>
        <box size="0.39 1 0.02"/>
      </geometry>
      <material name="White"/>
    </visual>
    <collision>
      <origin xyz="0 0 0"/>
      <geometry>
        <box size="0.39 1 0.02"/>
      </geometry>
    </collision>
    <inertial>
      <origin xyz="0 0 0"/>
      <mass value="10"/>
      <inertia ixx="0.8336666666666667" ixy="0" ixz="0" iyy="0.12708333333333335" iyz="0" izz="0.9600833333333333"/>
    </inertial>
  </link>
  <joint name="wc_frame_h2_shelf_joint" type="fixed">
    <origin xyz="0.187 0 -0.135"/>
    <parent link="wc_frame_back_panel"/>
    <child link="wc_frame_h2_shelf"/>
  </joint>
  <link name="wall_cabinet_c1_door">
    <visual>
      <origin xyz="0 0.298 0"/>
      <geometry>
        <box size="0.016 0.596 0.806"/>
      </geometry>
      <material name="Oak"/>
    </visual>
    <collision>
      <origin xyz="0 0.298 0"/>
      <geometry>
        <box size="0.016 0.596 0.806"/>
      </geometry>
    </collision>
    <inertial>
      <origin xyz="0 0.298 0"/>
      <mass value="3.31"/>
      <inertia ixx="0.2771716766666667" ixy="0" ixz="0" iyy="0.1792618766666667" iyz="0" izz="0.09805102666666665"/>
    </inertial>
  </link>
  <joint name="wall_cabinet_c1_door_joint" type="revolute">
    <parent link="wc_frame_back_panel"/>
    <child link="wall_cabinet_c1_door"/>
    <limit effort="10" lower="0" upper="1.5707963267948966" velocity="1"/>
    <dynamics damping="100" friction="0.1"/>
    <origin xyz="0.39 -0.5 0"/>
    <axis xyz="0 0 -1"/>
  </joint>
  <link name="wall_cabinet_c1_door_handle_link">
    <visual>
      <origin rpy="0 0 0" xyz="0 0 0"/>
      <geometry>
        <mesh filename="package://clover_lab/meshes/handle.stl"/>
      </geometry>
      <material name="Black"/>
    </visual>
    <collision>
      <origin rpy="0 0 0" xyz="0 0 0"/>
      <geometry>
        <mesh filename="package://clover_lab/meshes/handle.stl"/>
      </geometry>
    </collision>
    <inertial>
      <mass value="0.09"/>
      <origin xyz="0 0 0"/>
      <inertia ixx="0.000211711" ixy="0" ixz="0" iyy="6.3764e-05" iyz="0" izz="0.000274426"/>
    </inertial>
  </link>
  <joint name="wall_cabinet_c1_door_handle_joint" type="fixed">
    <parent link="wall_cabinet_c1_door"/>
    <child link="wall_cabinet_c1_door_handle_link"/>
    <origin rpy="0 0 0" xyz="0.008 0.48 -0.35"/>
  </joint>
  <link name="wall_cabinet_c2_door">
    <visual>
      <origin xyz="0 -0.198 0"/>
      <geometry>
        <box size="0.016 0.396 0.806"/>
      </geometry>
      <material name="Oak"/>
    </visual>
    <collision>
      <origin xyz="0 -0.198 0"/>
      <geometry>
        <box size="0.016 0.396 0.806"/>
      </geometry>
    </collision>
    <inertial>
      <origin xyz="0 -0.198 0"/>
      <mass value="3.31"/>
      <inertia ixx="0.22244634333333338" ixy="0" ixz="0" iyy="0.1792618766666667" iyz="0" izz="0.04332569333333334"/>
    </inertial>
  </link>
  <joint name="wall_cabinet_c2_door_joint" type="revolute">
    <parent link="wc_frame_back_panel"/>
    <child link="wall_cabinet_c2_door"/>
    <limit effort="10" lower="0" upper="1.5707963267948966" velocity="1"/>
    <dynamics damping="100" friction="0.1"/>
    <origin xyz="0.39 0.5 0"/>
    <axis xyz="0 0 1"/>
  </joint>
  <link name="wall_cabinet_c2_door_handle_link">
    <visual>
      <origin rpy="0 0 0" xyz="0 0 0"/>
      <geometry>
        <mesh filename="package://clover_lab/meshes/handle.stl"/>
      </geometry>
      <material name="Black"/>
    </visual>
    <collision>
      <origin rpy="0 0 0" xyz="0 0 0"/>
      <geometry>
        <mesh filename="package://clover_lab/meshes/handle.stl"/>
      </geometry>
    </collision>
    <inertial>
      <mass value="0.09"/>
      <origin xyz="0 0 0"/>
      <inertia ixx="0.000211711" ixy="0" ixz="0" iyy="6.3764e-05" iyz="0" izz="0.000274426"/>
    </inertial>
  </link>
  <joint name="wall_cabinet_c2_door_handle_joint" type="fixed">
    <parent link="wall_cabinet_c2_door"/>
    <child link="wall_cabinet_c2_door_handle_link"/>
    <origin rpy="0 0 0" xyz="0.008 -0.28 -0.35"/>
  </joint>
</robot>

